<?xml version="1.0" encoding="utf-8"?>
<!-- This URDF was automatically created by SolidWorks to URDF Exporter! Originally created by Stephen Brawner (brawner@gmail.com) 
     Commit Version: 1.6.0-4-g7f85cfe  Build Version: 1.6.7995.38578
     For more information, please see http://wiki.ros.org/sw_urdf_exporter -->
<robot
  name="vacbot">
  <link
    name="base_link">
    <inertial>
      <origin
        xyz="0.00332591076919364 1.65151878331327E-06 -0.0175827079026559"
        rpy="0 0 0" />
      <mass
        value="1.35286638383304" />
      <inertia
        ixx="0.00521045939867892"
        ixy="1.20848530476391E-07"
        ixz="1.65344441773012E-05"
        iyy="0.00526141082590494"
        iyz="2.16681689416479E-08"
        izz="0.00940007834641815" />
    </inertial>
    <visual>
      <origin
        xyz="0 0 0"
        rpy="0 0 0" />
      <geometry>
        <mesh
          filename="package://vacbot/meshes/base_link.STL" />
      </geometry>
      <material
        name="">
        <color
          rgba="0.537254901960784 0.349019607843137 0.337254901960784 1" />
      </material>
    </visual>
    <collision>
      <origin
        xyz="0 0 0"
        rpy="0 0 0" />
      <geometry>
        <mesh
          filename="package://vacbot/meshes/base_link.STL" />
      </geometry>
    </collision>
  </link>
  <link
    name="right_wheel">
    <inertial>
      <origin
        xyz="-2.77555756156289E-17 -2.77555756156289E-17 0"
        rpy="0 0 0" />
      <mass
        value="0.0724822295504708" />
      <inertia
        ixx="2.94732051060975E-05"
        ixy="-2.02034277851798E-36"
        ixz="-1.06800606831602E-35"
        iyy="5.63474018761707E-05"
        iyz="-9.2905867500558E-20"
        izz="2.94732051060975E-05" />
    </inertial>
    <visual>
      <origin
        xyz="0 0 0"
        rpy="0 0 0" />
      <geometry>
        <mesh
          filename="package://vacbot/meshes/right_wheel.STL" />
      </geometry>
      <material
        name="">
        <color
          rgba="0.792156862745098 0.819607843137255 0.933333333333333 1" />
      </material>
    </visual>
    <collision>
      <origin
        xyz="0 0 0"
        rpy="0 0 0" />
      <geometry>
        <mesh
          filename="package://vacbot/meshes/right_wheel.STL" />
      </geometry>
    </collision>
  </link>
  <joint
    name="right_joint"
    type="continuous">
    <origin
      xyz="0.015 -0.09 -0.025"
      rpy="0 0 0" />
    <parent
      link="base_link" />
    <child
      link="right_wheel" />
    <axis
      xyz="0 -1 0" />
    <limit
      effort="1"
      velocity="1" />
  </joint>
  <link
    name="left_wheel">
    <inertial>
      <origin
        xyz="0 0 -1.38777878078145E-17"
        rpy="0 0 0" />
      <mass
        value="0.0724822295504708" />
      <inertia
        ixx="2.94732051060975E-05"
        ixy="-1.26802639399171E-36"
        ixz="-1.06800606831602E-35"
        iyy="5.63474018761706E-05"
        iyz="-9.2905867500558E-20"
        izz="2.94732051060975E-05" />
    </inertial>
    <visual>
      <origin
        xyz="0 0 0"
        rpy="0 0 0" />
      <geometry>
        <mesh
          filename="package://vacbot/meshes/left_link.STL" />
      </geometry>
      <material
        name="">
        <color
          rgba="0.792156862745098 0.819607843137255 0.933333333333333 1" />
      </material>
    </visual>
    <collision>
      <origin
        xyz="0 0 0"
        rpy="0 0 0" />
      <geometry>
        <mesh
          filename="package://vacbot/meshes/left_link.STL" />
      </geometry>
    </collision>
  </link>
  <joint
    name="left_joint"
    type="continuous">
    <origin
      xyz="0.015 0.09 -0.025"
      rpy="0 0 0" />
    <parent
      link="base_link" />
    <child
      link="left_wheel" />
    <axis
      xyz="0 -1 0" />
    <limit
      effort="1"
      velocity="1" />
  </joint>
  <link
    name="lidar">
    <inertial>
      <origin
        xyz="0.00701820465484088 -9.55933157581884E-05 -0.00678186574337436"
        rpy="0 0 0" />
      <mass
        value="1.27729502358401" />
      <inertia
        ixx="0.000593155004344454"
        ixy="-8.30781519063116E-07"
        ixz="0.000162730950395812"
        iyy="0.000933018731061213"
        iyz="-3.17002772661671E-06"
        izz="0.00106895549805298" />
    </inertial>
    <visual>
      <origin
        xyz="0 0 0"
        rpy="0 0 0" />
      <geometry>
        <mesh
          filename="package://vacbot/meshes/lidar.STL" />
      </geometry>
      <material
        name="">
        <color
          rgba="0.792156862745098 0.819607843137255 0.933333333333333 1" />
      </material>
    </visual>
    <collision>
      <origin
        xyz="0 0 0"
        rpy="0 0 0" />
      <geometry>
        <mesh
          filename="package://vacbot/meshes/lidar.STL" />
      </geometry>
    </collision>
  </link>
  <joint
    name="lidar_joint"
    type="fixed">
    <origin
      xyz="-0.015 0 0.05305"
      rpy="0 0 0" />
    <parent
      link="base_link" />
    <child
      link="lidar" />
    <axis
      xyz="0 0 0" />
    <limit
      effort="0"
      velocity="0" />
  </joint>

  <gazebo>
  <plugin name="differential_drive_controller" filename="libgazebo_ros_diff_drive.so">
    <updateRate>100</updateRate>
    <leftJoint>left_joint</leftJoint>
    <rightJoint>right_joint</rightJoint>
    <wheelSeparation>0.18</wheelSeparation>
    <wheelDiameter>0.08</wheelDiameter>
    <wheelAcceleration>-0.01</wheelAcceleration>
    <wheelTorque>10</wheelTorque>
    <commandTopic>cmd_vel</commandTopic>
    <odometryTopic>odom</odometryTopic>
    <odometryFrame>odom</odometryFrame>
    <robotBaseFrame>base_footprint</robotBaseFrame>
    <odometrySource>1</odometrySource>
    <publishWheelTF>true</publishWheelTF>
    <publishOdom>true</publishOdom>
    <publishWheelJointState>true</publishWheelJointState>
    <legacyMode>false</legacyMode>
  </plugin>
</gazebo>

<gazebo reference="lidar">
    <sensor type="ray" name="head_rplidar_sensor">
      <pose>0 0 0 0 0 0</pose>
      <visualize>true</visualize>
      <update_rate>40</update_rate>
      <ray>
        <scan>
          <horizontal>
            <samples>720</samples>
            <resolution>1</resolution>
            <min_angle>-1.57</min_angle>
            <max_angle>1.57</max_angle>
          </horizontal>
        </scan>
        <range>
          <min>0.2</min>
          <max>8</max>
          <resolution>0.01</resolution>
        </range>
        <noise>
          <type>gaussian</type>
          <mean>0.0</mean>
          <stddev>0.01</stddev>
        </noise>
      </ray>
      <plugin name='laser' filename='libgazebo_ros_laser.so'>
        <topicName>m2wr/laser_scan</topicName>
        <frameName>lidar</frameName>
        <always_on>1</always_on>
        <update_rate>40</update_rate>
      </plugin>
    </sensor>
  </gazebo>
</robot>
